Workbook

Sheet Undertakings
A1: undertaking_id | B1: application_id | C1: institution_id | D1: obligation_type | E1: obligation_description | F1: source_reference | G1: is_verified_regulatory_requirement | H1: is_demo_rule | I1: issued_date | J1: due_date | K1: submitted_date | L1: assigned_role | M1: undertaking_status | N1: evidence_document_id | O1: verification_outcome | P1: verified_by | Q1: verified_date | R1: last_updated | S1: demo_notes
A2: UND-2026-001 | B2: APP012 | C2: INST012 | D2: AFFIDAVIT_SUBMISSION | E2: Submission of registered Society/Trust compliance affidavit on non-judicial stamp paper | F2: UNVERIFIED — DEMO CONFIGURATION | G2: FALSE | H2: TRUE | I2: 46319 | J2: 46349 | L2: ROLE_INSTITUTION_ADMIN | M2: AWAITING_SUBMISSION | O2: PENDING | R2: 46319 | S2: Reconciled to APP012 / INST012. Preserved synthetic draft/affidavit scenario for workflow testing.
A3: UND-2026-002 | B3: APP011 | C3: INST011 | D3: TER_FEE_CHALLAN | E3: TER payment receipt and bank transaction reconciliation undertaking | F3: UNVERIFIED — DEMO CONFIGURATION | G3: FALSE | H3: TRUE | I3: 46313 | J3: 46320 | L3: ROLE_INSTITUTION_ADMIN | M3: DUE_SOON | O3: PENDING | R3: 46319 | S3: Reconciled to APP011 / INST011. 7-day payment window ends on reference date 2026-10-25; marked Due Soon.
A4: UND-2026-003 | B4: APP-2026-1024 | C4: 1-109283724 | D4: ODL_SECURITY_COMPLIANCE | E4: Undertaking on remote proctoring cybersecurity standards and student data privacy | F4: UNVERIFIED — DEMO CONFIGURATION | G4: FALSE | H4: TRUE | I4: 46305 | J4: 46319 | L4: ROLE_INSTITUTION_ADMIN | M4: OVERDUE | O4: DEFICIENT | R4: 46320 | S4: FLAGGED FK CONFLICT: 1-109283724 has no master match in Dataset 1 (INST001-INST015); in Dataset 2 APP024 maps to INST009. Preserved original IDs and overdue scenario without guessing.
A5: UND-2026-004 | B5: APP002 | C5: INST002 | D5: FIRE_SAFETY_NOC | E5: Submission of renewed Fire & Emergency Services NOC for additional floor area | F5: UNVERIFIED — DEMO CONFIGURATION | G5: FALSE | H5: TRUE | I5: 46313 | J5: 46323 | K5: 46318 | L5: ROLE_RO_CASE_WORKER | M5: SUBMITTED | N5: DOC-2026-8812 | O5: PENDING | R5: 46318 | S5: Reconciled to APP002 / INST002. Fire safety certificate uploaded by institution; awaiting RO queue assignment.
A6: UND-2026-005 | B6: APP004 | C6: INST004 | D6: FACULTY_CADRE_RATIO | E6: Undertaking and appointment orders confirming faculty-to-student cadre ratio compliance | F6: UNVERIFIED — DEMO CONFIGURATION | G6: FALSE | H6: TRUE | I6: 46310 | J6: 46320 | K6: 46315 | L6: ROLE_SCRUTINY_MEMBER | M6: AWAITING_VERIFICATION | N6: DOC-2026-8819 | O6: PENDING | R6: 46316 | S6: Reconciled to APP004 / INST004. Faculty credentials uploaded; currently in active scrutiny panel evaluation queue.
A7: UND-2026-006 | B7: APP-2026-1019 | C7: 1-109283719 | D7: VENTILATION_COMPLIANCE | E7: Architectural blueprint and mechanical ventilation certificate for commercial training kitchen | F7: UNVERIFIED — DEMO CONFIGURATION | G7: FALSE | H7: TRUE | I7: 46311 | J7: 46321 | K7: 46317 | L7: ROLE_INSTITUTION_ADMIN | M7: CORRECTION_REQUESTED | N7: DOC-2026-8790 | O7: REVISION_REQUIRED | P7: ROLE_SCRUTINY_MEMBER | Q7: 46319 | R7: 46319 | S7: FLAGGED FK CONFLICT: 1-109283719 has no master match in Dataset 1 (INST001-INST015); in Dataset 2 APP019 maps to INST004. Preserved original IDs and correction scenario without guessing.
A8: UND-2026-007 | B8: APP008 | C8: INST008 | D8: LMS_PORTAL_AFFIDAVIT | E8: Affidavit certifying high-availability cloud infrastructure and 24x7 learner support LMS portal | F8: UNVERIFIED — DEMO CONFIGURATION | G8: FALSE | H8: TRUE | I8: 46296 | J8: 46310 | K8: 46305 | L8: ROLE_APPROVAL_BUREAU | M8: VERIFIED | N8: DOC-2026-8604 | O8: APPROVED | P8: ROLE_SCRUTINY_MEMBER | Q8: 46317 | R8: 46317 | S8: Reconciled to APP008 / INST008. LMS cloud hosting demo verified; cleared for Executive Committee determination.
A9: UND-2026-008 | B9: APP010 | C9: INST010 | D9: MERGER_TRUST_RESOLUTION | E9: Joint resolution of sponsoring trusts regarding unified asset handover and student continuity | F9: UNVERIFIED — DEMO CONFIGURATION | G9: FALSE | H9: TRUE | I9: 46273 | J9: 46295 | K9: 46290 | L9: ROLE_REGIONAL_OFFICER | M9: VERIFIED | N9: DOC-2026-8512 | O9: APPROVED | P9: ROLE_REGIONAL_OFFICER | Q9: 46316 | R9: 46316 | S9: Reconciled to APP010 / INST010. On-site merger inspection confirmed asset transfer; RO endorsed approval.
A10: UND-2026-009 | B10: APP013 | C10: INST013 | D10: ENDOWMENT_FUND_DEPOSIT | E10: Fixed deposit receipt in joint name of AICTE and Trust as mandatory corpus security | F10: UNVERIFIED — DEMO CONFIGURATION | G10: FALSE | H10: TRUE | I10: 46249 | J10: 46280 | K10: 46275 | L10: ROLE_EXECUTIVE_COMMITTEE | M10: COMPLETED | N10: DOC-2026-8340 | O10: APPROVED | P10: ROLE_EXECUTIVE_COMMITTEE | Q10: 46295 | R10: 46295 | S10: Reconciled to APP013 / INST013. Corpus deposit verified and locked; final Letter of Approval (LoA) issued.
A11: UND-2026-010 | B11: APP001 | C11: INST001 | D11: EVC_GROUND_FACILITIES | E11: Readiness undertaking for physical inspection of laboratories, barrier-free access, and hostel | F11: UNVERIFIED — DEMO CONFIGURATION | G11: FALSE | H11: TRUE | I11: 46309 | J11: 46322 | K11: 46319 | L11: ROLE_EVC_EXPERT | M11: AWAITING_VERIFICATION | N11: DOC-2026-8855 | O11: PENDING | R11: 46319 | S11: Reconciled to APP001 / INST001. Ground readiness affidavit submitted; EVC committee scheduled for Oct 28 inspection.

Sheet Data_Dictionary
A1: Field_Name | B1: Field_Description | C1: Data_Type | D1: Example_Value | E1: Allowed_Values | F1: Validation_Requirements
A2: undertaking_id | B2: Unique alphanumeric identifier for each undertaking record | C2: String | D2: UND-2026-001 | E2: Pattern: UND-YYYY-NNN | F2: Mandatory; Primary key; Unique across workbook
A3: application_id | B3: AICTE regulatory application identifier referencing Applications Master (Dataset 2) | C3: String | D3: APP012 | E3: Valid Application IDs (APP001 to APP025) per Dataset 2 Master | F3: Mandatory; Foreign key referencing Dataset 2; Unmatched legacy keys flagged
A4: institution_id | B4: AICTE higher education institutional identifier referencing Institutions Master (Dataset 1) | C4: String | D4: INST012 | E4: Valid Institution IDs (INST001 to INST015) per Dataset 1 Master | F4: Mandatory; Foreign key referencing Dataset 1; Unmatched legacy keys flagged
A5: obligation_type | B5: Categorical classification of regulatory or compliance obligation | C5: String | D5: AFFIDAVIT_SUBMISSION | E5: AFFIDAVIT_SUBMISSION, TER_FEE_CHALLAN, ODL_SECURITY_COMPLIANCE, FIRE_SAFETY_NOC, FACULTY_CADRE_RATIO, VENTILATION_COMPLIANCE, LMS_PORTAL_AFFIDAVIT, MERGER_TRUST_RESOLUTION, ENDOWMENT_FUND_DEPOSIT, EVC_GROUND_FACILITIES | F5: Mandatory; Must match standard obligation nomenclature
A6: obligation_description | B6: Detailed description of the specific compliance requirement or submission expected | C6: Text | D6: Submission of registered Society/Trust compliance affidavit on non-judicial stamp paper | E6: Descriptive string | F6: Mandatory; Max 250 characters
A7: source_reference | B7: Statutory regulation clause, AICTE APH handbook section, or demo flag | C7: String | D7: UNVERIFIED — DEMO CONFIGURATION | E7: Regulatory section or 'UNVERIFIED — DEMO CONFIGURATION' | F7: Mandatory; Must cite valid legal clause or explicit demo banner
A8: is_verified_regulatory_requirement | B8: Boolean flag indicating whether obligation is verified against published AICTE norms | C8: Boolean | D8: FALSE | E8: TRUE, FALSE | F8: Mandatory; Set to FALSE for unverified synthetic rules
A9: is_demo_rule | B9: Boolean flag indicating whether rule exists solely for prototype demonstration | C9: Boolean | D9: TRUE | E9: TRUE, FALSE | F9: Mandatory; Set to TRUE for prototype-specific scenarios
A10: issued_date | B10: Date when compliance obligation or deficiency notice was issued | C10: Date (ISO 8601) | D10: 46319 | E10: YYYY-MM-DD | F10: Mandatory; Must be <= due_date
A11: due_date | B11: Statutory deadline or SLA cutoff date for fulfillment | C11: Date (ISO 8601) | D11: 46349 | E11: YYYY-MM-DD | F11: Mandatory; Must be >= issued_date
A12: submitted_date | B12: Date when evidence or compliance affidavit was uploaded by applicant | C12: Date (ISO 8601) | D12: 46318 | E12: YYYY-MM-DD, Blank | F12: Optional; Populated only once submitted; Must be >= issued_date
A13: assigned_role | B13: RBAC security role currently responsible for actioning or reviewing obligation | C13: String | D13: ROLE_INSTITUTION_ADMIN | E13: ROLE_INSTITUTION_ADMIN, ROLE_RO_CASE_WORKER, ROLE_SCRUTINY_MEMBER, ROLE_REGIONAL_OFFICER, ROLE_APPROVAL_BUREAU, ROLE_EXECUTIVE_COMMITTEE, ROLE_EVC_EXPERT, ROLE_SAC_CHAIR | F13: Mandatory; Must reference Role_Permissions catalog
A14: undertaking_status | B14: Current lifecycle state of compliance obligation | C14: String | D14: AWAITING_SUBMISSION | E14: AWAITING_SUBMISSION, SUBMITTED, AWAITING_VERIFICATION, CORRECTION_REQUESTED, VERIFIED, DUE_SOON, OVERDUE, COMPLETED | F14: Mandatory; Driven by reference date 2026-10-25 and workflow progression
A15: evidence_document_id | B15: Alphanumeric repository document ID of uploaded evidence or affidavit | C15: String | D15: DOC-2026-8812 | E15: Pattern: DOC-YYYY-NNNN, Blank | F15: Populated when submitted_date is not blank
A16: verification_outcome | B16: Evaluation result determined by assigned reviewing authority | C16: String | D16: APPROVED | E16: PENDING, APPROVED, REVISION_REQUIRED, DEFICIENT | F16: Mandatory; PENDING prior to verification; APPROVED/REVISION_REQUIRED/DEFICIENT post-review
A17: verified_by | B17: Role or officer identifier who conducted compliance verification | C17: String | D17: ROLE_SCRUTINY_MEMBER | E17: Role Code or Officer ID, Blank | F17: Populated when verification_outcome is not PENDING
A18: verified_date | B18: Date when verification review was concluded and logged | C18: Date (ISO 8601) | D18: 46317 | E18: YYYY-MM-DD, Blank | F18: Must be >= submitted_date; Populated when verified_by is present
A19: last_updated | B19: Timestamp or date of most recent record alteration or audit event | C19: Date (ISO 8601) | D19: 46319 | E19: YYYY-MM-DD | F19: Mandatory; Must be >= issued_date
A20: demo_notes | B20: Contextual explanatory annotations regarding workflow logic, SLA calculations, or edge cases | C20: Text | D20: Application in Draft stage; applicant preparing mandatory affidavit upload. | E20: Freeform string | F20: Optional; Explains synthetic context and testing scenarios

Sheet Read_Me
A1: Section | B1: Details
A2: Dataset Title & Purpose | B2: Dataset_5_Synthetic_Undertakings_and_Due_Dates: Built for SIH26262 AICTE Approval Workflow Automation and Compliance Monitoring prototype to track institutional obligations, statutory submissions, deficiency rectifications, and SLA timelines.
A3: Synthetic Data Status & Disclaimer | B3: SYNTHETIC DEMO DATASET: Developed strictly for demonstration and testing purposes. Contains no actual confidential institutional data. Unverified obligations are marked with 'UNVERIFIED — DEMO CONFIGURATION', is_verified_regulatory_requirement = FALSE, and is_demo_rule = TRUE to avoid inventing statutory mandates.
A4: Simulation Reference Date | B4: 2026-10-25: Used as the active anchor date for calculating dynamic due-soon (e.g. expiring on or within 3 days) and overdue (deadline elapsed) status states.
A5: Upstream Dataset Relationships | B5: Reconciled directly against Dataset 2 (Applications Master: APP001–APP025) and Dataset 1 (Institutions Master: INST001–INST015). 8 of 10 records maintain verified entity pairings (APP001/INST001, APP002/INST002, APP004/INST004, APP008/INST008, APP010/INST010, APP011/INST011, APP012/INST012, APP013/INST013). 2 records (UND-2026-003, UND-2026-006) preserve legacy IDs and are explicitly flagged due to foreign key conflicts without unverified guessing.
A6: Lifecycle Status Coverage | B6: Demonstrates full compliance lifecycle progression: AWAITING_SUBMISSION, DUE_SOON, OVERDUE, SUBMITTED, AWAITING_VERIFICATION, CORRECTION_REQUESTED, VERIFIED, and COMPLETED across past, present, and future statutory deadlines relative to 2026-10-25.
A7: Chronological & Logical Consistency | B7: Chronology strictly validated: issued_date <= submitted_date <= verified_date <= reference_date (2026-10-25). Overdue status is derived strictly from due date and submission state; overdue obligations never trigger automatic application rejection.
A8: Role-Based Access Control (RBAC) | B8: Assigned roles align with governance standards: ROLE_INSTITUTION_ADMIN (Applicant), ROLE_RO_CASE_WORKER (Desk Officer), ROLE_SCRUTINY_MEMBER (Scrutiny Panel), ROLE_REGIONAL_OFFICER, ROLE_APPROVAL_BUREAU, ROLE_EXECUTIVE_COMMITTEE, and ROLE_EVC_EXPERT.
A9: Integration & System Caveats | B9: 1. Reconciled foreign keys connect to Dataset 2 applications and Dataset 1 institutions; unmatched keys are audited in Validation Report VR-02. 2. Automated SLA timers monitor expiration relative to fixed benchmark 2026-10-25. 3. Evidence repository IDs adhere to DOC-YYYY-NNNN standard.
A10: Technical Formatting Standards | B10: All date attributes adhere to ISO 8601 (YYYY-MM-DD). Freeze rows applied, column widths auto-fitted, tabular number/text alignment standardized, and dynamic formula calculations linked to live records.

Sheet Validation_Report
B2: AICTE APPROVAL WORKFLOW — COMPLIANCE TRACKING & DATA VALIDATION REPORT | I2: Evaluation Reference Date | K2: Status
B3: Scope: Dataset_5_Undertakings_and_due_dates | Process: Regulatory Obligations & SLA Monitoring | Project: SIH26262 | I3: 46320 | K3: ACTIVE MONITORING
B5: TOTAL OBLIGATIONS | D5: OVERDUE & DUE SOON | F5: UNDER ACTIVE REVIEW | H5: VERIFIED & APPROVED | J5: DATA INTEGRITY AUDIT
B6: =COUNTA(Undertakings!A2:A11) -> 10 | D6: =COUNTIF(Undertakings!M2:M11,"OVERDUE")+COUNTIF(Undertakings!M2:M11,"DUE_SOON") -> 2 | F6: =COUNTIF(Undertakings!M2:M11,"AWAITING_VERIFICATION")+COUNTIF(Undertakings!M2:M11,"SUBMITTED")+COUNTIF(Undertakings!M2:M11,"CORRECTION_REQUESTED") -> 4 | H6: =COUNTIF(Undertakings!O2:O11,"APPROVED") -> 3 | J6: =COUNTIF(J10:J16,"PASS")/COUNTA(B10:B16) -> 0.85714286
B7: 10 Total Mandates Monitored | D7: =COUNTIF(Undertakings!M2:M11,"OVERDUE")&" Critical | "&COUNTIF(Undertakings!M2:M11,"DUE_SOON")&" Due Soon" -> 1 Critical | 1 Due Soon | F7: Scrutiny & Inspection Queues | H7: =TEXT(COUNTIF(Undertakings!O2:O11,"APPROVED")/COUNTA(Undertakings!A2:A11),"0.0%")&" Clearance Rate" -> 30.0% Clearance Rate | J7: =COUNTIF(J10:J16,"PASS")&" of "&COUNTA(B10:B16)&" Rules Passed" -> 6 of 7 Rules Passed
B9: Rule ID | C9: Attribute Tested | D9: Validation Standard & Rule Specification | E9: Scope / Logic | F9: Total Tested | G9: Passed | H9: Flagged | I9: Compliance % | J9: Audit Result | K9: Audit Findings & Remarks
B10: VR-01 | C10: undertaking_id | D10: Primary key uniqueness and UND-YYYY-NNN format | E10: Undertakings!A2:A11 | F10: =COUNTA(Undertakings!A2:A11) -> 10 | G10: =IFERROR(__xludf.DUMMYFUNCTION("COUNTUNIQUE(Undertakings!A2:A11)"),10.0) -> 10 | H10: =F10-G10 -> 0 | I10: =G10/F10 -> 1 | J10: =IF(H10=0,"PASS","FAIL") -> PASS | K10: All 10 IDs unique and conform to standard format
B11: VR-02 | C11: application_id & institution_id | D11: Mandatory foreign keys referencing active master entities (Dataset 2 & Dataset 1) | E11: Undertakings!B2:C11 | F11: =COUNTA(Undertakings!A2:A11) -> 10 | G11: =COUNTIFS(Undertakings!B2:B11,"APP0*",Undertakings!C2:C11,"INST0*") -> 8 | H11: =F11-G11 -> 2 | I11: =G11/F11 -> 0.8 | J11: =IF(H11=0,"PASS","FLAGGED") -> FLAGGED | K11: 8 verified master pairings; 2 legacy records flagged for foreign key mismatch (UND-2026-003, UND-2026-006)
B12: VR-03 | C12: due_date vs issued_date | D12: Chronological integrity: due_date >= issued_date | E12: Undertakings!I2:J11 | F12: =COUNTA(Undertakings!A2:A11) -> 10 | G12: =SUMPRODUCT(--(Undertakings!J2:J11>=Undertakings!I2:I11)) -> 10 | H12: =F12-G12 -> 0 | I12: =G12/F12 -> 1 | J12: =IF(H12=0,"PASS","FAIL") -> PASS | K12: All statutory due dates are strictly >= issued date
B13: VR-04 | C13: evidence_document_id | D13: Mandatory repository document ID when submitted | E13: Undertakings!K2:N11 | F13: =COUNTIF(Undertakings!K2:K11,"<>") -> 7 | G13: =COUNTIFS(Undertakings!K2:K11,"<>",Undertakings!N2:N11,"DOC-*") -> 7 | H13: =F13-G13 -> 0 | I13: =G13/F13 -> 1 | J13: =IF(H13=0,"PASS","FAIL") -> PASS | K13: 100% of submitted obligations have valid document IDs
B14: VR-05 | C14: verification_outcome & reviewer | D14: Officer sign-off populated for concluded reviews | E14: Undertakings!O2:Q11 | F14: =COUNTIF(Undertakings!O2:O11,"APPROVED")+COUNTIF(Undertakings!O2:O11,"REVISION_REQUIRED") -> 4 | G14: =COUNTIFS(Undertakings!O2:O11,"<>PENDING",Undertakings!P2:P11,"ROLE_*",Undertakings!Q2:Q11,"<>") -> 4 | H14: =F14-G14 -> 0 | I14: =G14/F14 -> 1 | J14: =IF(H14=0,"PASS","FAIL") -> PASS | K14: All 4 peer-reviewed decisions contain reviewer role and timestamp
B15: VR-06 | C15: undertaking_status | D15: Status values adhere to prescribed lifecycle ontology | E15: Undertakings!M2:M11 | F15: =COUNTA(Undertakings!A2:A11) -> 10 | G15: {=SUMPRODUCT(--ISNUMBER(MATCH(Undertakings!M2:M11,{"AWAITING_SUBMISSION","DUE_SOON","OVERDUE","SUBMITTED","AWAITING_VERIFICATION","CORRECTION_REQUESTED","VERIFIED","COMPLETED"},0)))} -> 10 | H15: =F15-G15 -> 0 | I15: =G15/F15 -> 1 | J15: =IF(H15=0,"PASS","FAIL") -> PASS | K15: All 10 records match authorized lifecycle states
B16: VR-07 | C16: is_verified_reg & is_demo | D16: Synthetic governance flags: FALSE verification & DEMO banner | E16: Undertakings!F2:H11 | F16: =COUNTA(Undertakings!A2:A11) -> 10 | G16: =COUNTIFS(Undertakings!G2:G11,FALSE,Undertakings!H2:H11,TRUE,Undertakings!F2:F11,"*DEMO*") -> 10 | H16: =F16-G16 -> 0 | I16: =G16/F16 -> 1 | J16: =IF(H16=0,"PASS","FAIL") -> PASS | K16: Governance banner and synthetic flags correctly asserted
B17: SUMMARY | C17: All 7 Audit Tests | D17: Comprehensive Data Dictionary & Regulatory Verification | E17: Dataset_5!A:S | F17: =SUM(F10:F16) -> 61 | G17: =SUM(G10:G16) -> 59 | H17: =SUM(H10:H16) -> 2 | I17: =G17/F17 -> 0.96721311 | J17: =IF(H17=0,"PASS","FLAGGED") -> FLAGGED | K17: =IF(H17=0,"Dataset 100% compliant with Data Dictionary specifications","6 of 7 audit rules PASS; VR-02 FLAGGED with 2 foreign key discrepancies") -> 6 of 7 audit rules PASS; VR-02 FLAGGED with 2 foreign key discrepancies
B19: Undertaking ID | C19: Institution & Application | D19: Obligation Type | E19: Statutory Due Date | F19: Submitted Date | G19: Assigned RBAC Role | H19: Lifecycle Status | I19: Days to Due (Ref 2026-10-25) | J19: Verification Outcome | K19: Action Required & Bottleneck Alert
B20: =Undertakings!A2 -> UND-2026-001 | C20: =Undertakings!C2&" ("&Undertakings!B2&")" -> INST012 (APP012) | D20: =Undertakings!D2 -> AFFIDAVIT_SUBMISSION | E20: =Undertakings!J2 -> 46349 | F20: =IF(ISBLANK(Undertakings!K2),"—",Undertakings!K2) -> — | G20: =Undertakings!L2 -> ROLE_INSTITUTION_ADMIN | H20: =Undertakings!M2 -> AWAITING_SUBMISSION | I20: =E20-$I$3 -> 29 | J20: =Undertakings!O2 -> PENDING | K20: =IFS(H20="OVERDUE","CRITICAL: SAC Hearing Escalation",H20="DUE_SOON","URGENT: Payment Challan Upload Due Today",H20="AWAITING_SUBMISSION","Applicant preparing affidavit upload",H20="AWAITING_VERIFICATION","Pending scrutiny panel review",H20="SUBMITTED","Awaiting RO queue assignment",H20="CORRECTION_REQUESTED","Revised upload pending from applicant",H20="VERIFIED","Scrutiny endorsed; committee sign-off",H20="COMPLETED","Closed; Letter of Approval issued",TRUE,"Routine monitoring") -> Applicant preparing affidavit upload
B21: =Undertakings!A3 -> UND-2026-002 | C21: =Undertakings!C3&" ("&Undertakings!B3&")" -> INST011 (APP011) | D21: =Undertakings!D3 -> TER_FEE_CHALLAN | E21: =Undertakings!J3 -> 46320 | F21: =IF(ISBLANK(Undertakings!K3),"—",Undertakings!K3) -> — | G21: =Undertakings!L3 -> ROLE_INSTITUTION_ADMIN | H21: =Undertakings!M3 -> DUE_SOON | I21: =E21-$I$3 -> 0 | J21: =Undertakings!O3 -> PENDING | K21: =IFS(H21="OVERDUE","CRITICAL: SAC Hearing Escalation",H21="DUE_SOON","URGENT: Payment Challan Upload Due Today",H21="AWAITING_SUBMISSION","Applicant preparing affidavit upload",H21="AWAITING_VERIFICATION","Pending scrutiny panel review",H21="SUBMITTED","Awaiting RO queue assignment",H21="CORRECTION_REQUESTED","Revised upload pending from applicant",H21="VERIFIED","Scrutiny endorsed; committee sign-off",H21="COMPLETED","Closed; Letter of Approval issued",TRUE,"Routine monitoring") -> URGENT: Payment Challan Upload Due Today
B22: =Undertakings!A4 -> UND-2026-003 | C22: =Undertakings!C4&" ("&Undertakings!B4&")" -> 1-109283724 (APP-2026-1024) | D22: =Undertakings!D4 -> ODL_SECURITY_COMPLIANCE | E22: =Undertakings!J4 -> 46319 | F22: =IF(ISBLANK(Undertakings!K4),"—",Undertakings!K4) -> — | G22: =Undertakings!L4 -> ROLE_INSTITUTION_ADMIN | H22: =Undertakings!M4 -> OVERDUE | I22: =E22-$I$3 -> -1 | J22: =Undertakings!O4 -> DEFICIENT | K22: =IFS(H22="OVERDUE","CRITICAL: SAC Hearing Escalation",H22="DUE_SOON","URGENT: Payment Challan Upload Due Today",H22="AWAITING_SUBMISSION","Applicant preparing affidavit upload",H22="AWAITING_VERIFICATION","Pending scrutiny panel review",H22="SUBMITTED","Awaiting RO queue assignment",H22="CORRECTION_REQUESTED","Revised upload pending from applicant",H22="VERIFIED","Scrutiny endorsed; committee sign-off",H22="COMPLETED","Closed; Letter of Approval issued",TRUE,"Routine monitoring") -> CRITICAL: SAC Hearing Escalation
B23: =Undertakings!A5 -> UND-2026-004 | C23: =Undertakings!C5&" ("&Undertakings!B5&")" -> INST002 (APP002) | D23: =Undertakings!D5 -> FIRE_SAFETY_NOC | E23: =Undertakings!J5 -> 46323 | F23: =IF(ISBLANK(Undertakings!K5),"—",Undertakings!K5) -> 46318 | G23: =Undertakings!L5 -> ROLE_RO_CASE_WORKER | H23: =Undertakings!M5 -> SUBMITTED | I23: =E23-$I$3 -> 3 | J23: =Undertakings!O5 -> PENDING | K23: =IFS(H23="OVERDUE","CRITICAL: SAC Hearing Escalation",H23="DUE_SOON","URGENT: Payment Challan Upload Due Today",H23="AWAITING_SUBMISSION","Applicant preparing affidavit upload",H23="AWAITING_VERIFICATION","Pending scrutiny panel review",H23="SUBMITTED","Awaiting RO queue assignment",H23="CORRECTION_REQUESTED","Revised upload pending from applicant",H23="VERIFIED","Scrutiny endorsed; committee sign-off",H23="COMPLETED","Closed; Letter of Approval issued",TRUE,"Routine monitoring") -> Awaiting RO queue assignment
B24: =Undertakings!A6 -> UND-2026-005 | C24: =Undertakings!C6&" ("&Undertakings!B6&")" -> INST004 (APP004) | D24: =Undertakings!D6 -> FACULTY_CADRE_RATIO | E24: =Undertakings!J6 -> 46320 | F24: =IF(ISBLANK(Undertakings!K6),"—",Undertakings!K6) -> 46315 | G24: =Undertakings!L6 -> ROLE_SCRUTINY_MEMBER | H24: =Undertakings!M6 -> AWAITING_VERIFICATION | I24: =E24-$I$3 -> 0 | J24: =Undertakings!O6 -> PENDING | K24: =IFS(H24="OVERDUE","CRITICAL: SAC Hearing Escalation",H24="DUE_SOON","URGENT: Payment Challan Upload Due Today",H24="AWAITING_SUBMISSION","Applicant preparing affidavit upload",H24="AWAITING_VERIFICATION","Pending scrutiny panel review",H24="SUBMITTED","Awaiting RO queue assignment",H24="CORRECTION_REQUESTED","Revised upload pending from applicant",H24="VERIFIED","Scrutiny endorsed; committee sign-off",H24="COMPLETED","Closed; Letter of Approval issued",TRUE,"Routine monitoring") -> Pending scrutiny panel review
B25: =Undertakings!A7 -> UND-2026-006 | C25: =Undertakings!C7&" ("&Undertakings!B7&")" -> 1-109283719 (APP-2026-1019) | D25: =Undertakings!D7 -> VENTILATION_COMPLIANCE | E25: =Undertakings!J7 -> 46321 | F25: =IF(ISBLANK(Undertakings!K7),"—",Undertakings!K7) -> 46317 | G25: =Undertakings!L7 -> ROLE_INSTITUTION_ADMIN | H25: =Undertakings!M7 -> CORRECTION_REQUESTED | I25: =E25-$I$3 -> 1 | J25: =Undertakings!O7 -> REVISION_REQUIRED | K25: =IFS(H25="OVERDUE","CRITICAL: SAC Hearing Escalation",H25="DUE_SOON","URGENT: Payment Challan Upload Due Today",H25="AWAITING_SUBMISSION","Applicant preparing affidavit upload",H25="AWAITING_VERIFICATION","Pending scrutiny panel review",H25="SUBMITTED","Awaiting RO queue assignment",H25="CORRECTION_REQUESTED","Revised upload pending from applicant",H25="VERIFIED","Scrutiny endorsed; committee sign-off",H25="COMPLETED","Closed; Letter of Approval issued",TRUE,"Routine monitoring") -> Revised upload pending from applicant
B26: =Undertakings!A8 -> UND-2026-007 | C26: =Undertakings!C8&" ("&Undertakings!B8&")" -> INST008 (APP008) | D26: =Undertakings!D8 -> LMS_PORTAL_AFFIDAVIT | E26: =Undertakings!J8 -> 46310 | F26: =IF(ISBLANK(Undertakings!K8),"—",Undertakings!K8) -> 46305 | G26: =Undertakings!L8 -> ROLE_APPROVAL_BUREAU | H26: =Undertakings!M8 -> VERIFIED | I26: =E26-$I$3 -> -10 | J26: =Undertakings!O8 -> APPROVED | K26: =IFS(H26="OVERDUE","CRITICAL: SAC Hearing Escalation",H26="DUE_SOON","URGENT: Payment Challan Upload Due Today",H26="AWAITING_SUBMISSION","Applicant preparing affidavit upload",H26="AWAITING_VERIFICATION","Pending scrutiny panel review",H26="SUBMITTED","Awaiting RO queue assignment",H26="CORRECTION_REQUESTED","Revised upload pending from applicant",H26="VERIFIED","Scrutiny endorsed; committee sign-off",H26="COMPLETED","Closed; Letter of Approval issued",TRUE,"Routine monitoring") -> Scrutiny endorsed; committee sign-off
B27: =Undertakings!A9 -> UND-2026-008 | C27: =Undertakings!C9&" ("&Undertakings!B9&")" -> INST010 (APP010) | D27: =Undertakings!D9 -> MERGER_TRUST_RESOLUTION | E27: =Undertakings!J9 -> 46295 | F27: =IF(ISBLANK(Undertakings!K9),"—",Undertakings!K9) -> 46290 | G27: =Undertakings!L9 -> ROLE_REGIONAL_OFFICER | H27: =Undertakings!M9 -> VERIFIED | I27: =E27-$I$3 -> -25 | J27: =Undertakings!O9 -> APPROVED | K27: =IFS(H27="OVERDUE","CRITICAL: SAC Hearing Escalation",H27="DUE_SOON","URGENT: Payment Challan Upload Due Today",H27="AWAITING_SUBMISSION","Applicant preparing affidavit upload",H27="AWAITING_VERIFICATION","Pending scrutiny panel review",H27="SUBMITTED","Awaiting RO queue assignment",H27="CORRECTION_REQUESTED","Revised upload pending from applicant",H27="VERIFIED","Scrutiny endorsed; committee sign-off",H27="COMPLETED","Closed; Letter of Approval issued",TRUE,"Routine monitoring") -> Scrutiny endorsed; committee sign-off
B28: =Undertakings!A10 -> UND-2026-009 | C28: =Undertakings!C10&" ("&Undertakings!B10&")" -> INST013 (APP013) | D28: =Undertakings!D10 -> ENDOWMENT_FUND_DEPOSIT | E28: =Undertakings!J10 -> 46280 | F28: =IF(ISBLANK(Undertakings!K10),"—",Undertakings!K10) -> 46275 | G28: =Undertakings!L10 -> ROLE_EXECUTIVE_COMMITTEE | H28: =Undertakings!M10 -> COMPLETED | I28: =E28-$I$3 -> -40 | J28: =Undertakings!O10 -> APPROVED | K28: =IFS(H28="OVERDUE","CRITICAL: SAC Hearing Escalation",H28="DUE_SOON","URGENT: Payment Challan Upload Due Today",H28="AWAITING_SUBMISSION","Applicant preparing affidavit upload",H28="AWAITING_VERIFICATION","Pending scrutiny panel review",H28="SUBMITTED","Awaiting RO queue assignment",H28="CORRECTION_REQUESTED","Revised upload pending from applicant",H28="VERIFIED","Scrutiny endorsed; committee sign-off",H28="COMPLETED","Closed; Letter of Approval issued",TRUE,"Routine monitoring") -> Closed; Letter of Approval issued
B29: =Undertakings!A11 -> UND-2026-010 | C29: =Undertakings!C11&" ("&Undertakings!B11&")" -> INST001 (APP001) | D29: =Undertakings!D11 -> EVC_GROUND_FACILITIES | E29: =Undertakings!J11 -> 46322 | F29: =IF(ISBLANK(Undertakings!K11),"—",Undertakings!K11) -> 46319 | G29: =Undertakings!L11 -> ROLE_EVC_EXPERT | H29: =Undertakings!M11 -> AWAITING_VERIFICATION | I29: =E29-$I$3 -> 2 | J29: =Undertakings!O11 -> PENDING | K29: =IFS(H29="OVERDUE","CRITICAL: SAC Hearing Escalation",H29="DUE_SOON","URGENT: Payment Challan Upload Due Today",H29="AWAITING_SUBMISSION","Applicant preparing affidavit upload",H29="AWAITING_VERIFICATION","Pending scrutiny panel review",H29="SUBMITTED","Awaiting RO queue assignment",H29="CORRECTION_REQUESTED","Revised upload pending from applicant",H29="VERIFIED","Scrutiny endorsed; committee sign-off",H29="COMPLETED","Closed; Letter of Approval issued",TRUE,"Routine monitoring") -> Pending scrutiny panel review
B30: SLA METRICS | C30: 10 Obligations Tracked | D30: All Mandate Types | E30: Anchor: 2026-10-25 | F30: =COUNTIF(F20:F29,"<>—")&" Uploaded" -> 7 Uploaded | G30: 7 Review Roles | H30: =COUNTIF(H20:H29,"OVERDUE")&" Overdue | "&COUNTIF(H20:H29,"DUE_SOON")&" Due Soon" -> 1 Overdue | 1 Due Soon | I30: =ROUND(AVERAGE(I20:I29),1) -> -4.1 | J30: =COUNTIF(J20:J29,"APPROVED")&" Approved" -> 3 Approved | K30: Action required on 2 urgent items
B31: SLA Legend: Days to Due is computed dynamically relative to Reference Date 2026-10-25 ($I$3). Negative values denote days elapsed past statutory cutoff.
B33: INSTITUTION COMPLIANCE & RISK BREAKDOWN | G33: VERIFICATION OUTCOME & WORKFLOW DISTRIBUTION
B34: Institution ID | C34: Application ID | D34: Obligation Status | E34: Verification Outcome | F34: SLA / Risk Level | G34: Category / Status | H34: Classification | I34: Record Count | J34: Share of Total | K34: Operational Status / Action
B35: INST001 | C35: APP001 | D35: =VLOOKUP(B35,Undertakings!C$2:M$11,11,FALSE) -> AWAITING_VERIFICATION | E35: =VLOOKUP(B35,Undertakings!C$2:O$11,13,FALSE) -> PENDING | F35: On Track (EVC Inspection) | G35: APPROVED | H35: Verification Outcome | I35: =COUNTIF(Undertakings!O$2:O$11,"APPROVED") -> 3 | J35: =I35/COUNTA(Undertakings!A$2:A$11) -> 0.3 | K35: Cleared & Endorsed by Authority
B36: INST002 | C36: APP002 | D36: =VLOOKUP(B36,Undertakings!C$2:M$11,11,FALSE) -> SUBMITTED | E36: =VLOOKUP(B36,Undertakings!C$2:O$11,13,FALSE) -> PENDING | F36: On Track (RO Queue) | G36: REVISION_REQUIRED | H36: Verification Outcome | I36: =COUNTIF(Undertakings!O$2:O$11,"REVISION_REQUIRED") -> 1 | J36: =I36/COUNTA(Undertakings!A$2:A$11) -> 0.1 | K36: Applicant Resubmission Required
B37: INST004 | C37: APP004 | D37: =VLOOKUP(B37,Undertakings!C$2:M$11,11,FALSE) -> AWAITING_VERIFICATION | E37: =VLOOKUP(B37,Undertakings!C$2:O$11,13,FALSE) -> PENDING | F37: In Review (Scrutiny) | G37: DEFICIENT | H37: Verification Outcome | I37: =COUNTIF(Undertakings!O$2:O$11,"DEFICIENT") -> 1 | J37: =I37/COUNTA(Undertakings!A$2:A$11) -> 0.1 | K37: SLA Missed; Standing Appeal Panel
B38: INST008 | C38: APP008 | D38: =VLOOKUP(B38,Undertakings!C$2:M$11,11,FALSE) -> VERIFIED | E38: =VLOOKUP(B38,Undertakings!C$2:O$11,13,FALSE) -> APPROVED | F38: Cleared (Verified) | G38: PENDING | H38: Verification Outcome | I38: =COUNTIF(Undertakings!O$2:O$11,"PENDING") -> 5 | J38: =I38/COUNTA(Undertakings!A$2:A$11) -> 0.5 | K38: In Submission or Review Pipeline
B39: INST010 | C39: APP010 | D39: =VLOOKUP(B39,Undertakings!C$2:M$11,11,FALSE) -> VERIFIED | E39: =VLOOKUP(B39,Undertakings!C$2:O$11,13,FALSE) -> APPROVED | F39: Cleared (Verified) | G39: AWAITING_SUBMISSION | H39: Lifecycle Status | I39: =COUNTIF(Undertakings!M$2:M$11,"AWAITING_SUBMISSION") -> 1 | J39: =I39/COUNTA(Undertakings!A$2:A$11) -> 0.1 | K39: Draft stage applicant upload
B40: INST011 | C40: APP011 | D40: =VLOOKUP(B40,Undertakings!C$2:M$11,11,FALSE) -> DUE_SOON | E40: =VLOOKUP(B40,Undertakings!C$2:O$11,13,FALSE) -> PENDING | F40: Attention (Due Today) | G40: DUE_SOON | H40: Lifecycle Status | I40: =COUNTIF(Undertakings!M$2:M$11,"DUE_SOON") -> 1 | J40: =I40/COUNTA(Undertakings!A$2:A$11) -> 0.1 | K40: Expires today on anchor date
B41: INST012 | C41: APP012 | D41: =VLOOKUP(B41,Undertakings!C$2:M$11,11,FALSE) -> AWAITING_SUBMISSION | E41: =VLOOKUP(B41,Undertakings!C$2:O$11,13,FALSE) -> PENDING | F41: Pending Upload | G41: OVERDUE | H41: Lifecycle Status | I41: =COUNTIF(Undertakings!M$2:M$11,"OVERDUE") -> 1 | J41: =I41/COUNTA(Undertakings!A$2:A$11) -> 0.1 | K41: SLA breach; SAC escalation
B42: INST013 | C42: APP013 | D42: =VLOOKUP(B42,Undertakings!C$2:M$11,11,FALSE) -> COMPLETED | E42: =VLOOKUP(B42,Undertakings!C$2:O$11,13,FALSE) -> APPROVED | F42: Cleared (Completed) | G42: AWAITING_VERIFICATION | H42: Lifecycle Status | I42: =COUNTIF(Undertakings!M$2:M$11,"AWAITING_VERIFICATION") -> 2 | J42: =I42/COUNTA(Undertakings!A$2:A$11) -> 0.2 | K42: Active scrutiny evaluation
B43: 1-109283719 | C43: APP-2026-1019 | D43: =VLOOKUP(B43,Undertakings!C$2:M$11,11,FALSE) -> CORRECTION_REQUESTED | E43: =VLOOKUP(B43,Undertakings!C$2:O$11,13,FALSE) -> REVISION_REQUIRED | F43: Deficiency (Revision Req.) | FK Conflict | G43: CORRECTION_REQUESTED | H43: Lifecycle Status | I43: =COUNTIF(Undertakings!M$2:M$11,"CORRECTION_REQUESTED") -> 1 | J43: =I43/COUNTA(Undertakings!A$2:A$11) -> 0.1 | K43: Awaiting applicant correction
B44: 1-109283724 | C44: APP-2026-1024 | D44: =VLOOKUP(B44,Undertakings!C$2:M$11,11,FALSE) -> OVERDUE | E44: =VLOOKUP(B44,Undertakings!C$2:O$11,13,FALSE) -> DEFICIENT | F44: CRITICAL (Overdue SLA) | FK Conflict | G44: VERIFIED & COMPLETED | H44: Lifecycle Status | I44: =COUNTIF(Undertakings!M$2:M$11,"VERIFIED")+COUNTIF(Undertakings!M$2:M$11,"COMPLETED") -> 3 | J44: =I44/COUNTA(Undertakings!A$2:A$11) -> 0.3 | K44: Final bureau sign-off / LoA
B45: PORTFOLIO TOTAL | C45: 10 Institutions | D45: =COUNTIF(D35:D44,"OVERDUE")&" Overdue" -> 1 Overdue | E45: =COUNTIF(E35:E44,"APPROVED")&" Approved" -> 3 Approved | F45: 1 Overdue | 1 Due Soon | G45: OUTCOME TOTAL | H45: All 10 Obligations | I45: =SUM(I35:I38) -> 10 | J45: =SUM(J35:J38) -> 1 | K45: 100.0% Regulatory Accountability
...
